<mujoco model="MANO_right">

    <body name="wrist" gravcomp="1">
        <joint name="RootTx" axis="1 0 0" type="slide" damping="1"/>
        <joint name="RootTy" axis="0 1 0" type="slide" damping="1"/>
        <joint name="RootTz" axis="0 0 1" type="slide" damping="1"/>
        <joint name="RootR" type="ball"/>
        <inertial
            mass="0.2621651489812583"
            pos="-0.03428792862784619 -0.001983360201199018 4.859569785971209e-05"
            fullinertia="0.00013912170083065 0.000297873039439277 0.0002243946637740311 -1.155307773191229e-05 9.671338918447545e-07 -1.049928211703001e-06"
        />
        <geom class="visual" mesh="right_wrist" pos="-0.0956699401140213 -0.006383428350090981 -0.006186304613947868"/>
        <geom class="collision" size="0.015 0.01178445138" pos="-0.0144538301974535 -0.009313400834798813 0.01548770722001791" quat="0.913582 0.220263 -0.341835 2.45984e-13"/>
        <geom class="collision" type="box" size="0.0439 0.0135 0.035" pos="-0.03922105953097343 -0.003785171080380678 -0.0006308349594473838" quat="0.996311 0.00681974 -0.0706646 0.0482078"/>

        <!-- Thumb -->
        <body name="thumb1" gravcomp="1" pos="-0.02408971637487411 -0.01552233379334211 0.02581284381449223">
            <joint name="Thumb1R" type="ball"/>
            <inertial
                mass="0.01389095525951898"
                pos="-0.005365142091468073 -0.002576591731301335 0.01297582060630504"
                fullinertia="1.284009306496808e-06 1.807529504286183e-06 1.856666870777373e-06 -1.454644559940222e-07 1.572922643450275e-07 -3.475811205794311e-07"
            />
            <geom class="visual" mesh="right_thumb1" pos="-0.07158022373914719 0.009138905443251133 -0.03199914842844009"/>
            <geom class="collision" size="0.01 0.0103942164" pos="-0.006628209725022316 0.0003008996718563139 0.008001001551747322" quat="0.940679 -0.0153872 -0.338948 -7.02563e-17"/>
            <body name="thumb2" gravcomp="1" pos="-0.01963324472308159 0.0008912868797779083 0.0236995555460453">
                <joint name="Thumb2R" type="ball"/>
                <inertial
                    mass="0.008175178965760945"
                    pos="-0.01075580107062461 -0.002345119908563989 0.008481227041064993"
                    fullinertia="4.497509026165561e-07 6.380552594404862e-07 6.580969996922209e-07 -3.182897992888485e-08 5.071783866382185e-08 2.504411759822494e-08"
                />
                <geom class="visual" mesh="right_thumb2" pos="-0.0519469790160656 0.008247618563473225 -0.0556987039744854"/>
                <geom class="collision" size="0.01 0.00854709453" pos="-0.007008775603026152 -0.00171387754380703 0.004581758752465248" quat="0.876373 0.114404 -0.467848 9.71445e-17"/>
                <body name="thumb3" gravcomp="1" pos="-0.02221773564815521 -0.005432971753180027 0.01452412083745003">
                    <joint name="Thumb3R" type="ball"/>
                    <inertial
                        mass="0.00747772344623321"
                        pos="-0.01179746517184554 -0.002270360268563636 0.009189612105652695"
                        fullinertia="4.504282205664598e-07 6.644178756137688e-07 5.591522617414576e-07 -4.038463243261303e-08 1.721710210247788e-07 4.827619220538332e-08"
                    />
                    <geom class="visual" mesh="right_thumb3" pos="-0.02972924336791039 0.01368059031665325 -0.07022282481193542"/>
                    <geom class="collision" size="0.01 0.01399016533" pos="-0.01142392981416996 -0.002460023821868162 0.007691998220689819" quat="0.880288 0.0998761 -0.463808 3.19189e-16"/>
                </body>
            </body>
        </body>

        <!-- Ring finger -->
        <body name="ring1" gravcomp="1" pos="-0.08173556625843048 -0.003957420587539673 -0.02667319029569626">
            <joint name="Ring1R" type="ball"/>
            <inertial
                mass="0.007566219384225672"
                pos="-0.01229362562996941 0.002478270156332958 -0.0006989646432877111"
                fullinertia="3.725577298656618e-07 5.796986474490755e-07 5.795735664698766e-07 -5.569118446057833e-09 -4.869270235624241e-08 -9.515256953178793e-09"
            />
            <geom class="visual" mesh="right_ring1" pos="-0.01393437385559082 -0.002426007762551308 0.02048688568174839"/>
            <geom class="collision" size="0.008999999999999999 0.00892190818" pos="-0.009739752858877182 0.000711024331394583 -0.001753832912072539" quat="0.641575 -0.0558486 -0.765025 -3.05311e-16"/>
            <body name="ring2" gravcomp="1" pos="-0.02831427380442619 0.002067007124423981 -0.005098538473248482">
                <joint name="Ring2R" type="ball"/>
                <inertial
                    mass="0.005029987599785342"
                    pos="-0.01120108747821226 -0.0003899902702547342 -0.004202645694517223"
                    fullinertia="1.789927406775117e-07 3.470513046564063e-07 3.275264948956767e-07 -1.576526576054183e-08 -4.868308432861158e-08 -6.36215768749042e-09"
                />
                <geom class="visual" mesh="right_ring2" pos="0.01437989994883537 -0.004493014886975288 0.02558542415499687"/>
                <geom class="collision" size="0.0075 0.0086429372" pos="-0.008201702497899532 -0.0005886515136808157 -0.002661943435668945" quat="0.588222 0.057893 -0.806625 -5.55112e-17"/>
                <body name="ring3" gravcomp="1" pos="-0.02352051809430122 -0.001688111573457718 -0.007633816450834274">
                    <joint name="Ring3R" type="ball"/>
                    <inertial
                        mass="0.00288134705822775"
                        pos="-0.01199416619961559 -8.532674859326739e-05 -0.003519108567331522"
                        fullinertia="6.96075106575108e-08 1.392429752399229e-07 1.255906757718e-07 3.500704841988125e-09 -1.945298534824255e-08 -1.229084363579012e-09"
                    />
                    <geom class="visual" mesh="right_ring3" pos="0.0379004180431366 -0.00280490331351757 0.03321924060583115"/>
                    <geom class="collision" size="0.0075 0.0090144358" pos="-0.008628424416764247 0.0003032926320860706 -0.002591979665581778" quat="0.596852 -0.0281856 -0.801856 9.02056e-17"/>
                </body>
            </body>
        </body>

        <!-- Pinky finger -->
        <body name="pinky1" gravcomp="1" pos="-0.06878697872161865 -0.009940328076481819 -0.04320933669805527">
            <joint name="Pinky1R" type="ball"/>
            <inertial
                mass="0.00429689371005088"
                pos="-0.007298340700857824 0.001209671288326417 -0.007077038184132051"
                fullinertia="1.681797734422877e-07 2.244614664283673e-07 1.941109395838989e-07 -8.006221661156753e-10 -2.956527084550618e-08 -1.741624467465072e-09"
            />
            <geom class="visual" mesh="right_pinky1" pos="-0.02688296139240265 0.003556899726390839 0.03702303022146225"/>
            <geom class="collision" size="0.008999999999999999 0.00605596396" pos="-0.004880589433014393 1.773456642695237e-05 -0.003585279919207096" quat="0.45165 -0.00324194 -0.892189 -1.12757e-16"/>
            <body name="pinky2" gravcomp="1" pos="-0.01701441034674644 6.182515062391758e-05 -0.01249878108501434">
                <joint name="Pinky2R" type="ball"/>
                <inertial
                    mass="0.002781613790564921"
                    pos="-0.007860466243023591 0.001082534402904419 -0.006184610881384799"
                    fullinertia="8.10232289354825e-08 1.084056993496749e-07 9.615634712802696e-08 -1.827691227174668e-09 -1.49144378232804e-08 -4.39051464243735e-09"
                />
                <geom class="visual" mesh="right_pinky2" pos="-0.009868551045656204 0.003495074575766921 0.04952181130647659"/>
                <geom class="collision" size="0.0075 0.00572344303" pos="-0.004793046973645687 -0.0002087832690449432 -0.003121043555438519" quat="0.476808 0.038253 -0.878175 -2.22045e-16"/>
                <body name="pinky3" gravcomp="1" pos="-0.01586690172553062 -0.0006911561358720064 -0.0103319026529789">
                    <joint name="Pinky3R" type="ball"/>
                    <inertial
                        mass="0.001566057855040921"
                        pos="-0.008810483659855921 -0.0009578335233779781 -0.005027785409461583"
                        fullinertia="2.960281534014635e-08 4.43738299343363e-08 3.785476479004187e-08 2.583004582544436e-11 -6.313325860791448e-09 -4.851731346720774e-10"
                    />
                    <geom class="visual" mesh="right_pinky3" pos="0.00599835067987442 0.004186230711638927 0.05985371395945549"/>
                    <geom class="collision" size="0.0065 0.00675872644" pos="-0.005771451704418715 -0.0004900273787599806 -0.00348290132177909" quat="0.492281 0.0736398 -0.867316 7.63278e-17"/>
                </body>
            </body>
        </body>

        <!-- Middle finger -->
        <body name="middle1" gravcomp="1" pos="-0.09466045349836349 -0.001478962600231171 -0.003357539651915431">
            <joint name="Middle1R" type="ball"/>
            <inertial
                mass="0.01041232271134444"
                pos="-0.01404093428370029 0.002369654630678607 -0.002975534943670234"
                fullinertia="5.691079252468613e-07 1.201105062575942e-06 1.125634937693622e-06 5.156376283079277e-10 -1.424316691619549e-07 -9.47773545413763e-09"
            />
            <geom class="visual" mesh="right_middle1" pos="-0.001009486615657806 -0.00490446574985981 -0.002828764962032437"/>
            <geom class="collision" size="0.008999999999999999 0.0183675909" pos="-0.0111696794629097 0.0006667306879535317 -0.002003961941227317" quat="0.64176 -0.0456961 -0.765543 -2.35922e-16"/>
            <body name="middle2" gravcomp="1" pos="-0.03118266724050045 0.001861328259110451 -0.005594509653747082">
                <joint name="Middle2R" type="ball"/>
                <inertial
                    mass="0.004134916987366405"
                    pos="-0.01308363736227514 -0.0002096533445448924 -0.002215308889885086"
                    fullinertia="1.495346703662589e-07 2.028406094796937e-07 1.912160753708021e-07 -1.473680795106371e-08 -8.546669747643379e-09 -5.092232749750542e-09"
                />
                <geom class="visual" mesh="right_middle2" pos="0.03017318062484264 -0.006765794008970261 0.002765744691714644"/>
                <geom class="collision" size="0.0075 0.00788775473" pos="-0.007762070745229721 -0.0004243212752044201 -0.00133674219250679" quat="0.64441 0.0417397 -0.76354 -2.77556e-17"/>
                <body name="middle3" gravcomp="1" pos="-0.02290463633835316 -0.00125210452824831 -0.003944513387978077">
                    <joint name="Middle3R" type="ball"/>
                    <inertial
                        mass="0.003016592369827251"
                        pos="-0.01341204096573574 -0.0001321703788337673 -0.002081687520704607"
                        fullinertia="7.966680664410979e-08 1.371344583955573e-07 1.250475443711313e-07 8.157506841560311e-09 -1.255883708825473e-08 -1.105336821754682e-09"
                    />
                    <geom class="visual" mesh="right_middle3" pos="0.0530778169631958 -0.005513689480721951 0.006710258312523365"/>
                    <geom class="collision" size="0.0075 0.00926838158" pos="-0.009145713945442134 0.0003014557215035537 -0.001472391958602528" quat="0.648513 -0.0250767 -0.76079 2.63678e-16"/>
                </body>
            </body>
        </body>

        <!-- Index finger -->
        <body name="index1" gravcomp="1" pos="-0.08809725940227509 -0.005200356710702181 0.02068599313497543">
            <joint name="Index1R" type="ball"/>
            <inertial
                mass="0.008858013426270924"
                pos="-0.01841049225853478 0.003372971502468173 0.001485845999724966"
                fullinertia="4.441778858945276e-07 7.994890796984332e-07 8.307439886266915e-07 2.33849326666686e-08 3.18170695566891e-08 1.643036507892791e-10"
            />
            <geom class="visual" mesh="right_index1" pos="-0.007572680711746216 -0.0011830716393888 -0.0268722977489233"/>
            <geom class="collision" size="0.008999999999999999 0.01199924926" pos="-0.0118830343708396 0.001457922742702067 0.0008061919361352921" quat="0.730475 -0.0831659 -0.677857 -1.10084e-12"/>
            <body name="index2" gravcomp="1" pos="-0.03267890214920044 0.004009355790913105 0.002217065542936325">
                <joint name="Index2R" type="ball"/>
                <inertial
                    mass="0.004299645893867725"
                    pos="-0.0112130878785661 -0.0001671420303115973 2.323359852935206e-05"
                    fullinertia="1.542203558958309e-07 2.236098862551748e-07 2.046085210625759e-07 -8.907325254730415e-09 -1.088989905119781e-08 3.828831971148394e-09"
                />
                <geom class="visual" mesh="right_index2" pos="0.02510622143745422 -0.005192427430301905 -0.02908936329185963"/>
                <geom class="collision" size="0.0075 0.00734710801" pos="-0.007334427908062935 -0.0004298262647353113 -3.777751408051699e-05" quat="0.705287 0.0414745 -0.707708 1.37995e-12"/>
                <body name="index3" gravcomp="1" pos="-0.02215591073036194 -0.001298423390835524 -0.000114118680357933">
                    <joint name="Index3R" type="ball"/>
                    <inertial
                        mass="0.003095705087766235"
                        pos="-0.01113279506587959 -0.0005018619283154242 -0.0001430962173195431"
                        fullinertia="7.464031657849734e-08 1.572361421002517e-07 1.431567893291516e-07 1.575984661878876e-09 -7.061194366437685e-09 -4.29298608964218e-09"
                    />
                    <geom class="visual" mesh="right_index3" pos="0.04726213216781616 -0.003894004039466381 -0.02897524461150169"/>
                    <geom class="collision" size="0.0075 0.00902585808" pos="-0.009001294411288496 -0.0006414405166041191 -0.0001771079735335346" quat="0.700135 0.0507524 -0.712205 1.36802e-12"/>
                </body>
            </body>
        </body>
    </body>

</mujoco>
