<mujoco>
    <body name="doorknob_attachment" pos="-0.0825822262763977 -0.6478415727615356 0.9384804964065552">
        <body name="doorknob_sim" gravcomp="1" pos="-0.047 0 0" quat="0.47815212453295514 0.5128687163825603 -0.5009253359069297 -0.5073559237924161">
            <joint axis="0 0 1" limited="true" range="0 1" type="slide"/>
            <geom name="sim_geom_doorknob_visual" type="mesh" mesh="doorknob" contype="0" conaffinity="0" group="2" mass="0" rgba="0.8313 0.686 0.216 1.0"/>
            <geom name="sim_geom_doorknob_collision_knob" type="ellipsoid" size="0.0325 0.0325 0.015" pos="0 0 0.021" density="1250" condim="4" group="3" />
            <geom name="sim_geom_doorknob_collision_shaft" type="cylinder" size="0.01 0.0157" pos="0 0 -0.01" density="1250" condim="4" group="3" />
            <geom name="sim_geom_doorknob_collision_stopper" type="box" size="0.05 0.025 0.005" pos="0 0 -0.0315" density="1250" condim="4" group="3" />
            <include file="./contacts/sites/object_contact_sites.xml"/>
        </body>
    </body>
</mujoco>
